<?xml version="1.0"?>
<robot xmlns:xacro="http://www.ros.org/wiki/xacro" name="buff">

    <!-- 宏定义 -->
    <xacro:macro name="cylinder_inertial_matrix" params="m r h">
        <inertial>
            <mass value="${m}"/>
            <inertia ixx="${m*(3*r*r+h*h)/12}" ixy="0" ixz="0"
                     iyy="${m*(3*r*r+h*h)/12}" iyz="0"
                     izz="${m*r*r/2}"/>
        </inertial>
    </xacro:macro>
    <!-- 底座-->
    <link name="base_link"/>

    <!--立柱-->
    <xacro:property name="pillar_radius" value="0.05"/>
    <xacro:property name="pillar_length" value="1.0"/>
    <xacro:property name="pillar_m" value="2"/>
    <link name="pillar">
        <visual>
            <geometry>
                <cylinder radius="${pillar_radius}" length="${pillar_length}"/>
            </geometry>
            <origin xyz="0 0 0" rpy="0 0 0"/>
        </visual>
        <collision>
            <geometry>
                <cylinder radius="${pillar_radius}" length="${pillar_length}"/>
            </geometry>
            <origin xyz="0 0 0" rpy="0 0 0"/>
        </collision>
        <xacro:cylinder_inertial_matrix m="${pillar_m}" r="${pillar_radius}" h="${pillar_length}"/>
    </link>
    <!-- 关节 -->
    <joint name="base_to_pillar" type="fixed">
        <parent link="base_link"/>
        <child link="pillar"/>
        <origin xyz="0 0 0.5" rpy="0 0 0"/>
    </joint>
       <!-- 圆盘参数定义 -->
    <xacro:property name="disk_radius" value="0.3"/>
    <xacro:property name="disk_height" value="0.02"/>
    <xacro:property name="disk_mass" value="0.5"/>

    <!-- 圆盘link -->
    <link name="disk">
        <visual>
            <geometry>
                <cylinder radius="${disk_radius}" length="${disk_height}"/>
            </geometry>
            <origin xyz="0 0 0" rpy="0 ${pi/2} 0"/>
            <material name="blue">
                <color rgba="0 0 1 1"/>
            </material>
        </visual>
        <collision>
            <geometry>
                <cylinder radius="${disk_radius}" length="${disk_height}"/>
            </geometry>
            <origin xyz="0 0 0" rpy="0 ${pi/2} 0"/>
        </collision>
        <xacro:cylinder_inertial_matrix m="${disk_mass}" r="${disk_radius}" h="${disk_height}"/>
    </link>

    <!-- 立柱到圆盘的固定关节 -->
    <joint name="pillar_to_disk" type="continuous">
        <parent link="pillar"/>
        <child link="disk"/>
        <origin xyz="0.05 0 0.5" rpy="0 0 0"/>
        <axis xyz="1 0 0"/>
    </joint>

    <!-- 摆杆 -->
    <!-- 宏定义 -->
    <xacro:property name="arm_radius" value="0.02"/>
    <xacro:property name="arm_length" value="0.4"/>
    <xacro:property name="arm_m" value="0.5"/>
    <link name="buff_arm">
        <visual>
            <geometry>
                <cylinder radius="${arm_radius}" length="${arm_length}"/>
            </geometry>
            <origin xyz="0 0 0" rpy="0 0 0"/>
        </visual>
        <collision>
            <geometry>
                <cylinder radius="${arm_radius}" length="${arm_length}"/>
            </geometry>
            <origin xyz="0 0 0" rpy="0 0 0"/>
        </collision>
        <!-- 圆柱体的惯性矩阵 -->
        <xacro:cylinder_inertial_matrix m="${arm_m}" r="${arm_radius}" h="${arm_length}"/>
    </link>

    <!-- 关节 -->
    <joint name="rotating_joint" type="fixed">
        <parent link="disk"/>
        <child link="buff_arm"/>
        <origin xyz="0 0 0.5" rpy="0 0 0"/>
    </joint>
    <!-- 传动装置 -->

</robot>
